Workbook

Sheet Dashboard
A1: TCO Nissan Tiida — baseline atual para decisão de troca por EV
A3: Atualizado até | B3: 46278 | C3: Km/ano | D3: 21438 | E3: TCO central / mês | F3: 2304.55 | G3: TCO econômico / mês | H3: 2397.16
A5: 1. Histórico real — 12 meses móveis | F5: 2. Baseline para frente — cenário CENTRAL
A6: Componente | B6: Anual | C6: Mensal | D6: R$/km | F6: Componente | G6: Anual | H6: Mensal | I6: Lógica
A7: Combustível real | B7: 13267.21 | C7: =ROUND(B7/12,2) -> 1105.6 | D7: =ROUND(B7/$D$3,3) -> 0.619 | F7: Combustível otimizado | G7: 10858.57 | H7: =ROUND(G7/12,2) -> 904.88 | I7: Etanol: km/ano ÷ km/L × R$/L
A8: Serviços reais | B8: 17782.46 | C8: =ROUND(B8/12,2) -> 1481.87 | D8: =ROUND(B8/$D$3,3) -> 0.829 | F8: Manutenção central | G8: 11700.83 | H8: =ROUND(G8/12,2) -> 975.07 | I8: Histórico longo R$/km × uso atual
A9: Seguro | B9: 3516.24 | C9: =ROUND(B9/12,2) -> 293.02 | D9: =ROUND(B9/$D$3,3) -> 0.164 | F9: Seguro | G9: 3516.24 | H9: =ROUND(G9/12,2) -> 293.02 | I9: Custo atual
A10: IPVA estimado | B10: 1404.88 | C10: =ROUND(B10/12,2) -> 117.07 | D10: =ROUND(B10/$D$3,3) -> 0.066 | F10: IPVA | G10: 1404.88 | H10: =ROUND(G10/12,2) -> 117.07 | I10: Estimativa 2026
A11: Licenciamento | B11: 174.08 | C11: =ROUND(B11/12,2) -> 14.51 | D11: =ROUND(B11/$D$3,3) -> 0.008 | F11: Licenciamento | G11: 174.08 | H11: =ROUND(G11/12,2) -> 14.51 | I11: 2026
A12: TCO histórico real | B12: =ROUND(SUM(B7:B11),2) -> 36144.87 | C12: =ROUND(B12/12,2) -> 3012.07 | D12: =ROUND(B12/$D$3,3) -> 1.686 | F12: TCO de caixa CENTRAL | G12: =ROUND(SUM(G7:G11),2) -> 27654.6 | H12: =ROUND(G12/12,2) -> 2304.55 | I12: Base principal para comparar parcela
F13: Depreciação econômica | G13: 1111.32 | H13: =ROUND(G13/12,2) -> 92.61 | I13: 3% a.a. sobre FIPE atual
F14: TCO econômico CENTRAL | G14: =ROUND(G12+G13,2) -> 28765.92 | H14: =ROUND(G14/12,2) -> 2397.16 | I14: Caixa + depreciação
A16: 3. Sensibilidade da manutenção e do TCO
A17: Cenário | B17: Manutenção/ano | C17: TCO caixa/ano | D17: TCO caixa/mês | E17: TCO econômico/mês | F17: R$/km | G17: Uso | H17: Base | I17: Leitura
A18: Otimista | B18: 8739.46 | C18: =ROUND($G$7+B18+$G$9+$G$10+$G$11,2) -> 24693.23 | D18: =ROUND(C18/12,2) -> 2057.77 | E18: =ROUND((C18+$G$13)/12,2) -> 2150.38 | F18: =ROUND(C18/$D$3,3) -> 1.152 | G18: Piso | H18: 12m + corretivas/3 | I18: Grandes corretivas recentes não se repetem cedo
A19: CENTRAL — histórico longo | B19: 11700.83 | C19: =ROUND($G$7+B19+$G$9+$G$10+$G$11,2) -> 27654.6 | D19: =ROUND(C19/12,2) -> 2304.55 | E19: =ROUND((C19+$G$13)/12,2) -> 2397.16 | F19: =ROUND(C19/$D$3,3) -> 1.29 | G19: PRINCIPAL | H19: 2021–2026 | I19: Melhor caso-base para comparar EV
A20: Central+ — proxy externas | B20: 12881.2 | C20: =ROUND($G$7+B20+$G$9+$G$10+$G$11,2) -> 28834.97 | D20: =ROUND(C20/12,2) -> 2402.91 | E20: =ROUND((C20+$G$13)/12,2) -> 2495.52 | F20: =ROUND(C20/$D$3,3) -> 1.345 | G20: Sensibilidade | H20: Histórico + proxy | I20: Inclui referência de peças externas da OS 11032
A21: Stress — sua posse recente | B21: 15295.73 | C21: =ROUND($G$7+B21+$G$9+$G$10+$G$11,2) -> 31249.5 | D21: =ROUND(C21/12,2) -> 2604.13 | E21: =ROUND((C21+$G$13)/12,2) -> 2696.74 | F21: =ROUND(C21/$D$3,3) -> 1.458 | G21: Teto | H21: Jun/25–set/26 | I21: Mantém o ritmo recente de envelhecimento
A22: Histórico real 12m | B22: 17782.46 | C22: 36144.87 | D22: 3012.07 | E22: 3104.68 | F22: 1.686 | G22: Referência | H22: 12m móveis | I22: Fluxo real recente, não forecast
A24: 4. Manutenção — 12 meses móveis | F24: 5. Combustível — premissas atuais
A25: Categoria | B25: Valor | C25: % | D25: Tratamento | F25: Métrica | G25: Valor | H25: Unidade | I25: Leitura
A26: Preventiva / desgaste | B26: 4498.46 | C26: =B26/$B$29 -> 0.25297175 | D26: Recorrente / desgaste | F26: Etanol | G26: 3.89 | H26: R$/L | I26: Preço mais recente
A27: Corretiva / recuperação | B27: 12723 | C27: =B27/$B$29 -> 0.71548031 | D27: Usada em sensibilidade | F27: Gasolina | G27: 6.29 | H27: R$/L | I27: Preço mais recente
A28: Incidente / carroceria | B28: 561 | C28: =B28/$B$29 -> 0.031547941 | D28: Não recorrente | F28: Relação etanol/gasolina | G28: 0.6184 | H28: % | I28: Ainda favorável ao etanol
A29: Total serviços | B29: 17782.46 | D29: Histórico real | F29: Consumo etanol | G29: 7.68 | H29: km/L | I29: Referência histórica
F30: Custo projetado etanol | G30: 0.507 | H30: R$/km | I30: Usado no TCO para frente
A49: Leitura para decisão: use R$ 2,304.55/mês como baseline de caixa do Tiida e R$ 2,397.16/mês como baseline econômica. O histórico real dos últimos 12 meses foi R$ 3,012.07/mês. No Comparador_EV, a economia operacional deve ser confrontada com parcela, seguro, impostos, energia, manutenção e depreciação do elétrico.

Sheet Comparador_EV
A1: Comparador EV — compra, financiamento e custo real da troca
A2: Preencha as células amarelas. O número-chave é a PARCELA LÍQUIDA DA TROCA: financiamento + operação do EV − TCO de caixa do Tiida.
A4: 1. COMPRA DO ELÉTRICO | E4: 2. CONDIÇÕES DO FINANCIAMENTO | I4: 3. CUSTO OPERACIONAL DO EV
A5: Modelo / versão do EV | D5: Identificação do cenário | E5: Taxa de juros | F5: 0.017 | G5: % a.m. | H5: Taxa mensal da proposta | I5: Consumo elétrico | J5: 12 | K5: kWh/100 km | L5: Real ou homologado ajustado
A6: Preço do EV | B6: 120000 | C6: R$ | D6: Preço efetivo negociado | E6: Prazo original | F6: 48 | G6: meses | H6: Prazo contratado | I6: Tarifa elétrica | J6: 2 | K6: R$/kWh | L6: Tarifa efetiva de recarga
A7: FIPE atual do Tiida | B7: =Premissas!B11 -> 37044 | C7: R$ | D7: Referência automática | E7: Data da 1ª parcela | F7: 46266 | G7: data | H7: Atualize para cada proposta | I7: Perdas de recarga | J7: 0.1 | K7: % | L7: Wall-to-battery
A8: Valor líquido do Tiida na troca | B8: 40000 | C8: R$ | D8: Edite pelo valor real da proposta | E8: Correção monetária | F8: 0 | G8: % a.m. | H8: Mantida da sua calculadora | I8: Energia anual | J8: =IF(OR(J5="",J6=""),"",Dashboard!D3*J5/100*J6*(1+J7)) -> 5659.632 | K8: R$/ano | L8: Automático
A9: Entrada adicional em dinheiro | C9: R$ | D9: Além do Tiida | E9: Aporte extra padrão | F9: 0 | G9: R$/mês | H9: Amortização extra planejada | I9: Seguro EV | J9: 5600 | K9: R$/ano | L9: Cotação real
A10: Custos incorporados ao financiamento | C10: R$ | D10: Taxas/acessórios financiados | E10: Início do aporte | F10: 2 | G10: mês | H10: 1 = primeira parcela | I10: IPVA EV | J10: 4400 | K10: R$/ano | L10: Use 0 se aplicável
A11: Valor a financiar calculado | B11: =IF(B6="","",MAX(0,B6-B8-B9+B10)) -> 80000 | C11: R$ | D11: Preço - Tiida - entrada + custos | E11: Reinvestir redução da parcela? | F11: Sim | G11: Sim / Não | H11: Mantém o esforço financeiro mais alto | I11: Licenciamento | J11: =Premissas!B14 -> 174.08 | K11: R$/ano | L11: Base atual
A12: Valor financiado manual (opcional) | C12: R$ | D12: Usado enquanto o preço do EV estiver vazio | E12: Estratégia ativa | F12: =IF(B13<=0,"-",IF(AND(F9=0,COUNT(Financiamento_EV!I17:I136)=0),"BASELINE",IF(F11="Sim","POTENCIALIZADA","NORMAL"))) -> BASELINE | H12: Automático | I12: Manutenção EV | J12: 770 | K12: R$/ano | L12: Revisões + pneus + consumíveis
A13: VALOR FINANCIADO USADO | B13: =IF(B11<>"",B11,B12) -> 80000 | C13: R$ | D13: Base efetiva do simulador | E13: Orçamento financeiro após aporte | F13: =IF(Financiamento_EV!F5="","",Financiamento_EV!H5) -> 2451.511 | G13: R$/mês | H13: Parcela inicial + aporte padrão | I13: Depreciação EV | J13: 0.035 | K13: % a.a. | L13: Premissa econômica
I14: Depreciação anual | J14: =IF(OR(B6="",J13=""),"",B6*J13) -> 4200 | K14: R$/ano | L14: Automático
A15: 4. O QUE A TROCA SIGNIFICA NO SEU BOLSO | I15: TCO caixa EV | J15: =IF(COUNT(J8:J12)<5,"",SUM(J8:J12)) -> 16603.712 | K15: R$/ano | L15: Sem financiamento
A16: PAGAMENTO DO FINANCIAMENTO — MÊS 1 | C16: ECONOMIA OPERACIONAL VS TIIDA / MÊS | E16: PARCELA FINAL — CUSTO LÍQUIDO DA TROCA / MÊS 1 | I16: TCO caixa EV | J16: =IF(J15="","",J15/12) -> 1383.6427 | K16: R$/mês | L16: Sem financiamento
A17: =IF(Financiamento_EV!N17=0,"",Financiamento_EV!N17) -> 2451.511 | C17: =IF(J16="","",Dashboard!H12-J16) -> 920.90733 | E17: =IF(OR(A17="",C17=""),"",A17-C17) -> 1530.6036 | I17: TCO econômico EV | J17: =IF(OR(J15="",J14=""),"",(J15+J14)/12) -> 1733.6427 | K17: R$/mês | L17: Caixa + depreciação
A19: MÉDIA LÍQUIDA ATÉ A QUITAÇÃO | C19: DEPOIS DA QUITAÇÃO / MÊS | E19: QUITAÇÃO ESTIMADA
A20: =Fluxo_EV!D4 -> 1530.6036 | C20: =Fluxo_EV!F4 -> -920.90733 | E20: =Financiamento_EV!F7 -> 47696
A22: 5. TRÊS ESTRATÉGIAS DE FINANCIAMENTO
A23: BASELINE — SEM AMORTIZAÇÃO | C23: AMORTIZAÇÃO NORMAL | E23: POTENCIALIZADA
A24: Prazo efetivo | B24: =Cenarios_Fin!B5 -> 48 | C24: Prazo efetivo | D24: =Cenarios_Fin!D5 -> 48 | E24: Prazo efetivo | F24: =Cenarios_Fin!F5 -> 48
A25: Quitação | B25: =Cenarios_Fin!B6 -> 47696 | C25: Quitação | D25: =Cenarios_Fin!D6 -> 47696 | E25: Quitação | F25: =Cenarios_Fin!F6 -> 47696
A26: Juros totais | B26: =Cenarios_Fin!B7 -> 37672.526 | C26: Juros totais | D26: =Cenarios_Fin!D7 -> 37672.526 | E26: Juros totais | F26: =Cenarios_Fin!F7 -> 37672.526
A27: Total pago | B27: =Cenarios_Fin!B8 -> 117672.53 | C27: Total pago | D27: =Cenarios_Fin!D8 -> 117672.53 | E27: Total pago | F27: =Cenarios_Fin!F8 -> 117672.53
A28: Economia de juros | B28: =Cenarios_Fin!B9 -> 0 | C28: Economia de juros | D28: =Cenarios_Fin!D9 -> 0 | E28: Economia de juros | F28: =Cenarios_Fin!F9 -> 8.0035534e-11
A29: Meses antecipados | B29: =Cenarios_Fin!B10 -> 0 | C29: Meses antecipados | D29: =Cenarios_Fin!D10 -> 0 | E29: Meses antecipados | F29: =Cenarios_Fin!F10 -> 0
A31: 6. TCO E LEITURA ECONÔMICA
A32: Métrica | B32: Tiida | C32: EV | D32: Delta EV - Tiida
A33: TCO de caixa / mês | B33: =Dashboard!H12 -> 2304.55 | C33: =IF(J16="","",J16) -> 1383.6427 | D33: =IF(C33="","",C33-B33) -> -920.90733
A34: TCO econômico / mês | B34: =Dashboard!H14 -> 2397.16 | C34: =IF(J17="","",J17) -> 1733.6427 | D34: =IF(C34="","",C34-B34) -> -663.51733
A35: Juros médios / mês no financiamento | B35: 0 | C35: =IF(OR(Financiamento_EV!F8="",Financiamento_EV!F6=0),"",Financiamento_EV!F8/Financiamento_EV!F6) -> 784.84428 | D35: =IF(C35="","",C35) -> 784.84428
A36: Custo econômico EV + juros médios | B36: =Dashboard!H14 -> 2397.16 | C36: =IF(OR(J17="",C35=""),"",J17+C35) -> 2518.487 | D36: =IF(C36="","",C36-B36) -> 121.32695
A37: Total de juros do cenário ativo | B37: 0 | C37: =IF(Financiamento_EV!F8="","",Financiamento_EV!F8) -> 37672.526 | D37: =IF(C37="","",C37) -> 37672.526
A39: Parcela líquida = pagamento do financiamento + custo operacional do EV − TCO mensal do Tiida. Positivo é dinheiro novo por mês; negativo é economia.

Sheet Financiamento_EV
A1: Financiamento EV — amortização detalhada do cenário ativo
A2: Premissas em verde vêm do Comparador_EV. A coluna amarela 'Extra manual' substitui o aporte padrão em meses específicos. O modelo recalcula a parcela para o prazo remanescente após amortizações.
A4: PREMISSAS VINCULADAS | E4: RESUMO DO CENÁRIO ATIVO
A5: Valor financiado | C5: =Comparador_EV!$B$13 -> 80000 | E5: Parcela contratual inicial | F5: =IF($C$5<=0,"",IF($C$6=0,$C$5/$C$7,$C$5*$C$6/(1-(1+$C$6)^(-$C$7)))) -> 2451.511 | G5: Orçamento após aporte | H5: =IF(F5="","",F5+$C$10) -> 2451.511
A6: Taxa de juros a.m. | C6: =Comparador_EV!$F$5 -> 0.017 | E6: Prazo efetivo | F6: =IF($C$5<=0,"",IFERROR(MATCH(0,$O$17:$O$136,0),$C$7)) -> 48 | G6: Meses antecipados | H6: =IF(F6="","",$C$7-F6) -> 0
A7: Prazo original (meses) | C7: =Comparador_EV!F6 -> 48 | E7: Quitação estimada | F7: =IF($C$5<=0,"",IFERROR(INDEX($B$17:$B$136,MATCH(0,$O$17:$O$136,0)),"")) -> 47696 | G7: Economia de juros | H7: =IF(F8="","",Cenarios_Fin!$B$7-F8) -> 8.0035534e-11
A8: Data da 1ª parcela | C8: =Comparador_EV!$F$7 -> 46266 | E8: Juros totais | F8: =IF($C$5<=0,"",SUM($F$17:$F$136)) -> 37672.526 | G8: Economia de juros (%) | H8: =IF(OR(H7="",Cenarios_Fin!$B$7=0),"",H7/Cenarios_Fin!$B$7) -> 2.1245067e-15
A9: Correção monetária a.m. | C9: =Comparador_EV!$F$8 -> 0
A10: Aporte extra padrão | C10: =Comparador_EV!F9 -> 0 | E10: Aporte novo efetivo | F10: =IF($C$5<=0,"",SUM($L$17:$L$136)) -> 0 | G10: Total pago | H10: =IF($C$5<=0,"",SUM($N$17:$N$136)) -> 117672.53
A11: Início do aporte (mês) | C11: =Comparador_EV!$F$10 -> 2 | E11: Reinvestimento | F11: =IF($C$5<=0,"",SUM($M$17:$M$136)) -> 1.2773853e-09 | G11: Parcela contratual final | H11: =IF($C$5<=0,"",IFERROR(INDEX($G$17:$G$136,MATCH(0,$O$17:$O$136,0)),0)) -> 2451.511
A12: Reinvestir redução da parcela? | C12: =Comparador_EV!$F$11 -> Sim | E12: Amortização extra total | F12: =IF($C$5<=0,"",SUM($L$17:$M$136)) -> 1.2773853e-09 | G12: Redução da parcela final | H12: =IF(OR(F5="",H11=""),"",MAX(0,F5-H11)) -> 5.6525096e-10
A14: CRONOGRAMA DO CENÁRIO ATIVO
A15: Mês | B15: Referência | C15: Saldo inicial | D15: Correção | E15: Saldo corrigido | F15: Juros | G15: Parcela contratual | H15: Amortização da parcela | I15: Extra manual | J15: Aporte base | K15: Reinvestimento | L15: Aporte base efetivo | M15: Reinvest. efetivo | N15: Pagamento total | O15: Saldo final | P15: Juros acumulados | Q15: Extras acumulados
A17: =1 -> 1 | B17: =C8 -> 46266 | C17: =C5 -> 80000 | D17: =IF(OR(C17<=0,A17>$C$7),0,C17*$C$9) -> 0 | E17: =MAX(0,C17+D17) -> 80000 | F17: =IF(E17<=0,0,E17*$C$6) -> 1360 | G17: =IF(E17<=0,0,IF($C$6=0,E17/($C$7-A17+1),E17*$C$6/(1-(1+$C$6)^(-($C$7-A17+1))))) -> 2451.511 | H17: =MAX(0,MIN(E17,G17-F17)) -> 1091.511 | J17: =IF(E17<=0,0,IF(ISNUMBER(I17),MAX(0,I17),IF(A17>=$C$11,$C$10,0))) -> 0 | K17: =IF(OR(E17<=0,$C$12<>"Sim",A17<$C$11),0,MAX(0,$F$5-G17)) -> 0 | L17: =IF(E17<=0,0,MIN(J17,MAX(0,E17-H17))) -> 0 | M17: =IF(E17<=0,0,MIN(K17,MAX(0,E17-H17-L17))) -> 0 | N17: =IF(E17<=0,0,G17+L17+M17) -> 2451.511 | O17: =MAX(0,E17-H17-L17-M17) -> 78908.489 | P17: =F17 -> 1360 | Q17: =L17+M17 -> 0
A18: =A17+1 -> 2 | B18: =DATE(YEAR(B17),MONTH(B17)+1,1) -> 46296 | C18: =O17 -> 78908.489 | D18: =IF(OR(C18<=0,A18>$C$7),0,C18*$C$9) -> 0 | E18: =MAX(0,C18+D18) -> 78908.489 | F18: =IF(E18<=0,0,E18*$C$6) -> 1341.4443 | G18: =IF(E18<=0,0,IF($C$6=0,E18/($C$7-A18+1),E18*$C$6/(1-(1+$C$6)^(-($C$7-A18+1))))) -> 2451.511 | H18: =MAX(0,MIN(E18,G18-F18)) -> 1110.0666 | J18: =IF(E18<=0,0,IF(ISNUMBER(I18),MAX(0,I18),IF(A18>=$C$11,$C$10,0))) -> 0 | K18: =IF(OR(E18<=0,$C$12<>"Sim",A18<$C$11),0,MAX(0,$F$5-G18)) -> 0 | L18: =IF(E18<=0,0,MIN(J18,MAX(0,E18-H18))) -> 0 | M18: =IF(E18<=0,0,MIN(K18,MAX(0,E18-H18-L18))) -> 0 | N18: =IF(E18<=0,0,G18+L18+M18) -> 2451.511 | O18: =MAX(0,E18-H18-L18-M18) -> 77798.422 | P18: =P17+F18 -> 2701.4443 | Q18: =Q17+L18+M18 -> 0
A19: =A18+1 -> 3 | B19: =DATE(YEAR(B18),MONTH(B18)+1,1) -> 46327 | C19: =O18 -> 77798.422 | D19: =IF(OR(C19<=0,A19>$C$7),0,C19*$C$9) -> 0 | E19: =MAX(0,C19+D19) -> 77798.422 | F19: =IF(E19<=0,0,E19*$C$6) -> 1322.5732 | G19: =IF(E19<=0,0,IF($C$6=0,E19/($C$7-A19+1),E19*$C$6/(1-(1+$C$6)^(-($C$7-A19+1))))) -> 2451.511 | H19: =MAX(0,MIN(E19,G19-F19)) -> 1128.9378 | J19: =IF(E19<=0,0,IF(ISNUMBER(I19),MAX(0,I19),IF(A19>=$C$11,$C$10,0))) -> 0 | K19: =IF(OR(E19<=0,$C$12<>"Sim",A19<$C$11),0,MAX(0,$F$5-G19)) -> 9.094947e-13 | L19: =IF(E19<=0,0,MIN(J19,MAX(0,E19-H19))) -> 0 | M19: =IF(E19<=0,0,MIN(K19,MAX(0,E19-H19-L19))) -> 9.094947e-13 | N19: =IF(E19<=0,0,G19+L19+M19) -> 2451.511 | O19: =MAX(0,E19-H19-L19-M19) -> 76669.485 | P19: =P18+F19 -> 4024.0175 | Q19: =Q18+L19+M19 -> 9.094947e-13
A20: =A19+1 -> 4 | B20: =DATE(YEAR(B19),MONTH(B19)+1,1) -> 46357 | C20: =O19 -> 76669.485 | D20: =IF(OR(C20<=0,A20>$C$7),0,C20*$C$9) -> 0 | E20: =MAX(0,C20+D20) -> 76669.485 | F20: =IF(E20<=0,0,E20*$C$6) -> 1303.3812 | G20: =IF(E20<=0,0,IF($C$6=0,E20/($C$7-A20+1),E20*$C$6/(1-(1+$C$6)^(-($C$7-A20+1))))) -> 2451.511 | H20: =MAX(0,MIN(E20,G20-F20)) -> 1148.1297 | J20: =IF(E20<=0,0,IF(ISNUMBER(I20),MAX(0,I20),IF(A20>=$C$11,$C$10,0))) -> 0 | K20: =IF(OR(E20<=0,$C$12<>"Sim",A20<$C$11),0,MAX(0,$F$5-G20)) -> 4.5474735e-13 | L20: =IF(E20<=0,0,MIN(J20,MAX(0,E20-H20))) -> 0 | M20: =IF(E20<=0,0,MIN(K20,MAX(0,E20-H20-L20))) -> 4.5474735e-13 | N20: =IF(E20<=0,0,G20+L20+M20) -> 2451.511 | O20: =MAX(0,E20-H20-L20-M20) -> 75521.355 | P20: =P19+F20 -> 5327.3987 | Q20: =Q19+L20+M20 -> 1.3642421e-12
A21: =A20+1 -> 5 | B21: =DATE(YEAR(B20),MONTH(B20)+1,1) -> 46388 | C21: =O20 -> 75521.355 | D21: =IF(OR(C21<=0,A21>$C$7),0,C21*$C$9) -> 0 | E21: =MAX(0,C21+D21) -> 75521.355 | F21: =IF(E21<=0,0,E21*$C$6) -> 1283.863 | G21: =IF(E21<=0,0,IF($C$6=0,E21/($C$7-A21+1),E21*$C$6/(1-(1+$C$6)^(-($C$7-A21+1))))) -> 2451.511 | H21: =MAX(0,MIN(E21,G21-F21)) -> 1167.6479 | J21: =IF(E21<=0,0,IF(ISNUMBER(I21),MAX(0,I21),IF(A21>=$C$11,$C$10,0))) -> 0 | K21: =IF(OR(E21<=0,$C$12<>"Sim",A21<$C$11),0,MAX(0,$F$5-G21)) -> 9.094947e-13 | L21: =IF(E21<=0,0,MIN(J21,MAX(0,E21-H21))) -> 0 | M21: =IF(E21<=0,0,MIN(K21,MAX(0,E21-H21-L21))) -> 9.094947e-13 | N21: =IF(E21<=0,0,G21+L21+M21) -> 2451.511 | O21: =MAX(0,E21-H21-L21-M21) -> 74353.707 | P21: =P20+F21 -> 6611.2618 | Q21: =Q20+L21+M21 -> 2.2737368e-12
A22: =A21+1 -> 6 | B22: =DATE(YEAR(B21),MONTH(B21)+1,1) -> 46419 | C22: =O21 -> 74353.707 | D22: =IF(OR(C22<=0,A22>$C$7),0,C22*$C$9) -> 0 | E22: =MAX(0,C22+D22) -> 74353.707 | F22: =IF(E22<=0,0,E22*$C$6) -> 1264.013 | G22: =IF(E22<=0,0,IF($C$6=0,E22/($C$7-A22+1),E22*$C$6/(1-(1+$C$6)^(-($C$7-A22+1))))) -> 2451.511 | H22: =MAX(0,MIN(E22,G22-F22)) -> 1187.4979 | J22: =IF(E22<=0,0,IF(ISNUMBER(I22),MAX(0,I22),IF(A22>=$C$11,$C$10,0))) -> 0 | K22: =IF(OR(E22<=0,$C$12<>"Sim",A22<$C$11),0,MAX(0,$F$5-G22)) -> 9.094947e-13 | L22: =IF(E22<=0,0,MIN(J22,MAX(0,E22-H22))) -> 0 | M22: =IF(E22<=0,0,MIN(K22,MAX(0,E22-H22-L22))) -> 9.094947e-13 | N22: =IF(E22<=0,0,G22+L22+M22) -> 2451.511 | O22: =MAX(0,E22-H22-L22-M22) -> 73166.209 | P22: =P21+F22 -> 7875.2748 | Q22: =Q21+L22+M22 -> 3.1832315e-12
A23: =A22+1 -> 7 | B23: =DATE(YEAR(B22),MONTH(B22)+1,1) -> 46447 | C23: =O22 -> 73166.209 | D23: =IF(OR(C23<=0,A23>$C$7),0,C23*$C$9) -> 0 | E23: =MAX(0,C23+D23) -> 73166.209 | F23: =IF(E23<=0,0,E23*$C$6) -> 1243.8256 | G23: =IF(E23<=0,0,IF($C$6=0,E23/($C$7-A23+1),E23*$C$6/(1-(1+$C$6)^(-($C$7-A23+1))))) -> 2451.511 | H23: =MAX(0,MIN(E23,G23-F23)) -> 1207.6854 | J23: =IF(E23<=0,0,IF(ISNUMBER(I23),MAX(0,I23),IF(A23>=$C$11,$C$10,0))) -> 0 | K23: =IF(OR(E23<=0,$C$12<>"Sim",A23<$C$11),0,MAX(0,$F$5-G23)) -> 9.094947e-13 | L23: =IF(E23<=0,0,MIN(J23,MAX(0,E23-H23))) -> 0 | M23: =IF(E23<=0,0,MIN(K23,MAX(0,E23-H23-L23))) -> 9.094947e-13 | N23: =IF(E23<=0,0,G23+L23+M23) -> 2451.511 | O23: =MAX(0,E23-H23-L23-M23) -> 71958.524 | P23: =P22+F23 -> 9119.1003 | Q23: =Q22+L23+M23 -> 4.0927262e-12
A24: =A23+1 -> 8 | B24: =DATE(YEAR(B23),MONTH(B23)+1,1) -> 46478 | C24: =O23 -> 71958.524 | D24: =IF(OR(C24<=0,A24>$C$7),0,C24*$C$9) -> 0 | E24: =MAX(0,C24+D24) -> 71958.524 | F24: =IF(E24<=0,0,E24*$C$6) -> 1223.2949 | G24: =IF(E24<=0,0,IF($C$6=0,E24/($C$7-A24+1),E24*$C$6/(1-(1+$C$6)^(-($C$7-A24+1))))) -> 2451.511 | H24: =MAX(0,MIN(E24,G24-F24)) -> 1228.216 | J24: =IF(E24<=0,0,IF(ISNUMBER(I24),MAX(0,I24),IF(A24>=$C$11,$C$10,0))) -> 0 | K24: =IF(OR(E24<=0,$C$12<>"Sim",A24<$C$11),0,MAX(0,$F$5-G24)) -> 9.094947e-13 | L24: =IF(E24<=0,0,MIN(J24,MAX(0,E24-H24))) -> 0 | M24: =IF(E24<=0,0,MIN(K24,MAX(0,E24-H24-L24))) -> 9.094947e-13 | N24: =IF(E24<=0,0,G24+L24+M24) -> 2451.511 | O24: =MAX(0,E24-H24-L24-M24) -> 70730.308 | P24: =P23+F24 -> 10342.395 | Q24: =Q23+L24+M24 -> 5.0022209e-12
A25: =A24+1 -> 9 | B25: =DATE(YEAR(B24),MONTH(B24)+1,1) -> 46508 | C25: =O24 -> 70730.308 | D25: =IF(OR(C25<=0,A25>$C$7),0,C25*$C$9) -> 0 | E25: =MAX(0,C25+D25) -> 70730.308 | F25: =IF(E25<=0,0,E25*$C$6) -> 1202.4152 | G25: =IF(E25<=0,0,IF($C$6=0,E25/($C$7-A25+1),E25*$C$6/(1-(1+$C$6)^(-($C$7-A25+1))))) -> 2451.511 | H25: =MAX(0,MIN(E25,G25-F25)) -> 1249.0957 | J25: =IF(E25<=0,0,IF(ISNUMBER(I25),MAX(0,I25),IF(A25>=$C$11,$C$10,0))) -> 0 | K25: =IF(OR(E25<=0,$C$12<>"Sim",A25<$C$11),0,MAX(0,$F$5-G25)) -> 1.3642421e-12 | L25: =IF(E25<=0,0,MIN(J25,MAX(0,E25-H25))) -> 0 | M25: =IF(E25<=0,0,MIN(K25,MAX(0,E25-H25-L25))) -> 1.3642421e-12 | N25: =IF(E25<=0,0,G25+L25+M25) -> 2451.511 | O25: =MAX(0,E25-H25-L25-M25) -> 69481.212 | P25: =P24+F25 -> 11544.81 | Q25: =Q24+L25+M25 -> 6.3664629e-12
A26: =A25+1 -> 10 | B26: =DATE(YEAR(B25),MONTH(B25)+1,1) -> 46539 | C26: =O25 -> 69481.212 | D26: =IF(OR(C26<=0,A26>$C$7),0,C26*$C$9) -> 0 | E26: =MAX(0,C26+D26) -> 69481.212 | F26: =IF(E26<=0,0,E26*$C$6) -> 1181.1806 | G26: =IF(E26<=0,0,IF($C$6=0,E26/($C$7-A26+1),E26*$C$6/(1-(1+$C$6)^(-($C$7-A26+1))))) -> 2451.511 | H26: =MAX(0,MIN(E26,G26-F26)) -> 1270.3303 | J26: =IF(E26<=0,0,IF(ISNUMBER(I26),MAX(0,I26),IF(A26>=$C$11,$C$10,0))) -> 0 | K26: =IF(OR(E26<=0,$C$12<>"Sim",A26<$C$11),0,MAX(0,$F$5-G26)) -> 1.3642421e-12 | L26: =IF(E26<=0,0,MIN(J26,MAX(0,E26-H26))) -> 0 | M26: =IF(E26<=0,0,MIN(K26,MAX(0,E26-H26-L26))) -> 1.3642421e-12 | N26: =IF(E26<=0,0,G26+L26+M26) -> 2451.511 | O26: =MAX(0,E26-H26-L26-M26) -> 68210.882 | P26: =P25+F26 -> 12725.991 | Q26: =Q25+L26+M26 -> 7.730705e-12
A27: =A26+1 -> 11 | B27: =DATE(YEAR(B26),MONTH(B26)+1,1) -> 46569 | C27: =O26 -> 68210.882 | D27: =IF(OR(C27<=0,A27>$C$7),0,C27*$C$9) -> 0 | E27: =MAX(0,C27+D27) -> 68210.882 | F27: =IF(E27<=0,0,E27*$C$6) -> 1159.585 | G27: =IF(E27<=0,0,IF($C$6=0,E27/($C$7-A27+1),E27*$C$6/(1-(1+$C$6)^(-($C$7-A27+1))))) -> 2451.511 | H27: =MAX(0,MIN(E27,G27-F27)) -> 1291.926 | J27: =IF(E27<=0,0,IF(ISNUMBER(I27),MAX(0,I27),IF(A27>=$C$11,$C$10,0))) -> 0 | K27: =IF(OR(E27<=0,$C$12<>"Sim",A27<$C$11),0,MAX(0,$F$5-G27)) -> 2.2737368e-12 | L27: =IF(E27<=0,0,MIN(J27,MAX(0,E27-H27))) -> 0 | M27: =IF(E27<=0,0,MIN(K27,MAX(0,E27-H27-L27))) -> 2.2737368e-12 | N27: =IF(E27<=0,0,G27+L27+M27) -> 2451.511 | O27: =MAX(0,E27-H27-L27-M27) -> 66918.956 | P27: =P26+F27 -> 13885.576 | Q27: =Q26+L27+M27 -> 1.0004442e-11
A28: =A27+1 -> 12 | B28: =DATE(YEAR(B27),MONTH(B27)+1,1) -> 46600 | C28: =O27 -> 66918.956 | D28: =IF(OR(C28<=0,A28>$C$7),0,C28*$C$9) -> 0 | E28: =MAX(0,C28+D28) -> 66918.956 | F28: =IF(E28<=0,0,E28*$C$6) -> 1137.6222 | G28: =IF(E28<=0,0,IF($C$6=0,E28/($C$7-A28+1),E28*$C$6/(1-(1+$C$6)^(-($C$7-A28+1))))) -> 2451.511 | H28: =MAX(0,MIN(E28,G28-F28)) -> 1313.8887 | J28: =IF(E28<=0,0,IF(ISNUMBER(I28),MAX(0,I28),IF(A28>=$C$11,$C$10,0))) -> 0 | K28: =IF(OR(E28<=0,$C$12<>"Sim",A28<$C$11),0,MAX(0,$F$5-G28)) -> 1.8189894e-12 | L28: =IF(E28<=0,0,MIN(J28,MAX(0,E28-H28))) -> 0 | M28: =IF(E28<=0,0,MIN(K28,MAX(0,E28-H28-L28))) -> 1.8189894e-12 | N28: =IF(E28<=0,0,G28+L28+M28) -> 2451.511 | O28: =MAX(0,E28-H28-L28-M28) -> 65605.067 | P28: =P27+F28 -> 15023.198 | Q28: =Q27+L28+M28 -> 1.1823431e-11
A29: =A28+1 -> 13 | B29: =DATE(YEAR(B28),MONTH(B28)+1,1) -> 46631 | C29: =O28 -> 65605.067 | D29: =IF(OR(C29<=0,A29>$C$7),0,C29*$C$9) -> 0 | E29: =MAX(0,C29+D29) -> 65605.067 | F29: =IF(E29<=0,0,E29*$C$6) -> 1115.2861 | G29: =IF(E29<=0,0,IF($C$6=0,E29/($C$7-A29+1),E29*$C$6/(1-(1+$C$6)^(-($C$7-A29+1))))) -> 2451.511 | H29: =MAX(0,MIN(E29,G29-F29)) -> 1336.2248 | J29: =IF(E29<=0,0,IF(ISNUMBER(I29),MAX(0,I29),IF(A29>=$C$11,$C$10,0))) -> 0 | K29: =IF(OR(E29<=0,$C$12<>"Sim",A29<$C$11),0,MAX(0,$F$5-G29)) -> 2.7284841e-12 | L29: =IF(E29<=0,0,MIN(J29,MAX(0,E29-H29))) -> 0 | M29: =IF(E29<=0,0,MIN(K29,MAX(0,E29-H29-L29))) -> 2.7284841e-12 | N29: =IF(E29<=0,0,G29+L29+M29) -> 2451.511 | O29: =MAX(0,E29-H29-L29-M29) -> 64268.842 | P29: =P28+F29 -> 16138.484 | Q29: =Q28+L29+M29 -> 1.4551915e-11
... A136: =A135+1 -> 120 | B136: =DATE(YEAR(B135),MONTH(B135)+1,1) -> 49888 | C136: =O135 -> 0 | D136: =IF(OR(C136<=0,A136>$C$7),0,C136*$C$9) -> 0 | E136: =MAX(0,C136+D136) -> 0 | F136: =IF(E136<=0,0,E136*$C$6) -> 0 | G136: =IF(E136<=0,0,IF($C$6=0,E136/($C$7-A136+1),E136*$C$6/(1-(1+$C$6)^(-($C$7-A136+1))))) -> 0 | H136: =MAX(0,MIN(E136,G136-F136)) -> 0 | J136: =IF(E136<=0,0,IF(ISNUMBER(I136),MAX(0,I136),IF(A136>=$C$11,$C$10,0))) -> 0 | K136: =IF(OR(E136<=0,$C$12<>"Sim",A136<$C$11),0,MAX(0,$F$5-G136)) -> 0 | L136: =IF(E136<=0,0,MIN(J136,MAX(0,E136-H136))) -> 0 | M136: =IF(E136<=0,0,MIN(K136,MAX(0,E136-H136-L136))) -> 0 | N136: =IF(E136<=0,0,G136+L136+M136) -> 0 | O136: =MAX(0,E136-H136-L136-M136) -> 0 | P136: =P135+F136 -> 37672.526 | Q136: =Q135+L136+M136 -> 1.2773853e-09

Sheet Cenarios_Fin
A1: Financiamento — comparação de estratégias de amortização
A2: Baseline = sem amortização. Normal = aporte fixo. Potencializada = aporte fixo + reinvestimento da redução da parcela.
A4: BASELINE — SEM AMORTIZAÇÃO | C4: AMORTIZAÇÃO NORMAL | E4: POTENCIALIZADA
A5: Prazo efetivo | B5: =IF(Financiamento_EV!$C$5<=0,"",IFERROR(MATCH(0,$H$35:$H$154,0),Financiamento_EV!$C$7)) -> 48 | C5: Prazo efetivo | D5: =IF(Financiamento_EV!$C$5<=0,"",IFERROR(MATCH(0,$S$35:$S$154,0),Financiamento_EV!$C$7)) -> 48 | E5: Prazo efetivo | F5: =IF(Financiamento_EV!$C$5<=0,"",IFERROR(MATCH(0,$AF$35:$AF$154,0),Financiamento_EV!$C$7)) -> 48
A6: Quitação | B6: =IF(B5="","",DATE(YEAR(Financiamento_EV!$C$8),MONTH(Financiamento_EV!$C$8)+B5-1,1)) -> 47696 | C6: Quitação | D6: =IF(D5="","",DATE(YEAR(Financiamento_EV!$C$8),MONTH(Financiamento_EV!$C$8)+D5-1,1)) -> 47696 | E6: Quitação | F6: =IF(F5="","",DATE(YEAR(Financiamento_EV!$C$8),MONTH(Financiamento_EV!$C$8)+F5-1,1)) -> 47696
A7: Juros totais | B7: =IF(B5="","",SUM($E$35:$E$154)) -> 37672.526 | C7: Juros totais | D7: =IF(D5="","",SUM($O$35:$O$154)) -> 37672.526 | E7: Juros totais | F7: =IF(F5="","",SUM($Z$35:$Z$154)) -> 37672.526
A8: Total pago | B8: =IF(B5="","",SUM($I$35:$I$154)) -> 117672.53 | C8: Total pago | D8: =IF(D5="","",SUM($T$35:$T$154)) -> 117672.53 | E8: Total pago | F8: =IF(F5="","",SUM($AE$35:$AE$154)) -> 117672.53
A9: Economia de juros | B9: 0 | C9: Economia de juros | D9: =IF(D7="","",$B$7-D7) -> 0 | E9: Economia de juros | F9: =IF(F7="","",$B$7-F7) -> 8.0035534e-11
A10: Meses antecipados | B10: 0 | C10: Meses antecipados | D10: =IF(D5="","",Financiamento_EV!$C$7-D5) -> 0 | E10: Meses antecipados | F10: =IF(F5="","",Financiamento_EV!$C$7-F5) -> 0
A11: Extra total | B11: 0 | C11: Extra total | D11: =IF(D5="","",SUM($R$35:$R$154)) -> 0 | E11: Extra total | F11: =IF(F5="","",SUM($AG$35:$AG$154)) -> 1.2773853e-09
A34: Mês | B34: Saldo inicial | C34: Correção | D34: Saldo corrigido | E34: Juros | F34: Parcela | G34: Amort. | H34: Saldo final | I34: Pagamento | K34: Mês | L34: Saldo inicial | M34: Correção | N34: Saldo corrigido | O34: Juros | P34: Parcela | Q34: Amort. | R34: Aporte | S34: Saldo final | T34: Pagamento | V34: Mês | W34: Saldo inicial | X34: Correção | Y34: Saldo corrigido | Z34: Juros | AA34: Parcela | AB34: Amort. | AC34: Aporte | AD34: Reinvest. | AE34: Pagamento | AF34: Saldo final | AG34: Extra total | AI34: Mês | AJ34: Baseline | AK34: Normal | AL34: Potencializada | AM34: Mês | AN34: Baseline | AO34: Normal | AP34: Potencializada
A35: =1 -> 1 | B35: =Financiamento_EV!$C$5 -> 80000 | C35: =IF(OR(B35<=0,A35>Financiamento_EV!$C$7),0,B35*Financiamento_EV!$C$9) -> 0 | D35: =MAX(0,B35+C35) -> 80000 | E35: =IF(D35<=0,0,D35*Financiamento_EV!$C$6) -> 1360 | F35: =IF(D35<=0,0,IF(Financiamento_EV!$C$6=0,D35/(Financiamento_EV!$C$7-A35+1),D35*Financiamento_EV!$C$6/(1-(1+Financiamento_EV!$C$6)^(-(Financiamento_EV!$C$7-A35+1))))) -> 2451.511 | G35: =MAX(0,MIN(D35,F35-E35)) -> 1091.511 | H35: =MAX(0,D35-G35) -> 78908.489 | I35: =IF(D35<=0,0,F35) -> 2451.511 | K35: =1 -> 1 | L35: =Financiamento_EV!$C$5 -> 80000 | M35: =IF(OR(L35<=0,K35>Financiamento_EV!$C$7),0,L35*Financiamento_EV!$C$9) -> 0 | N35: =MAX(0,L35+M35) -> 80000 | O35: =IF(N35<=0,0,N35*Financiamento_EV!$C$6) -> 1360 | P35: =IF(N35<=0,0,IF(Financiamento_EV!$C$6=0,N35/(Financiamento_EV!$C$7-K35+1),N35*Financiamento_EV!$C$6/(1-(1+Financiamento_EV!$C$6)^(-(Financiamento_EV!$C$7-K35+1))))) -> 2451.511 | Q35: =MAX(0,MIN(N35,P35-O35)) -> 1091.511 | R35: =IF(N35<=0,0,MIN(IF(ISNUMBER(INDEX(Financiamento_EV!$I$17:$I$136,K35)),MAX(0,INDEX(Financiamento_EV!$I$17:$I$136,K35)),IF(K35>=Financiamento_EV!$C$11,Financiamento_EV!$C$10,0)),MAX(0,N35-Q35))) -> 0 | S35: =MAX(0,N35-Q35-R35) -> 78908.489 | T35: =IF(N35<=0,0,P35+R35) -> 2451.511 | V35: =1 -> 1 | W35: =Financiamento_EV!$C$5 -> 80000 | X35: =IF(OR(W35<=0,V35>Financiamento_EV!$C$7),0,W35*Financiamento_EV!$C$9) -> 0 | Y35: =MAX(0,W35+X35) -> 80000 | Z35: =IF(Y35<=0,0,Y35*Financiamento_EV!$C$6) -> 1360 | AA35: =IF(Y35<=0,0,IF(Financiamento_EV!$C$6=0,Y35/(Financiamento_EV!$C$7-V35+1),Y35*Financiamento_EV!$C$6/(1-(1+Financiamento_EV!$C$6)^(-(Financiamento_EV!$C$7-V35+1))))) -> 2451.511 | AB35: =MAX(0,MIN(Y35,AA35-Z35)) -> 1091.511 | AC35: =IF(Y35<=0,0,MIN(IF(ISNUMBER(INDEX(Financiamento_EV!$I$17:$I$136,V35)),MAX(0,INDEX(Financiamento_EV!$I$17:$I$136,V35)),IF(V35>=Financiamento_EV!$C$11,Financiamento_EV!$C$10,0)),MAX(0,Y35-AB35))) -> 0 | AD35: =IF(OR(Y35<=0,V35<Financiamento_EV!$C$11),0,MIN(MAX(0,Financiamento_EV!$F$5-AA35),MAX(0,Y35-AB35-AC35))) -> 0 | AE35: =IF(Y35<=0,0,AA35+AC35+AD35) -> 2451.511 | AF35: =MAX(0,Y35-AB35-AC35-AD35) -> 78908.489 | AG35: =AC35+AD35 -> 0 | AI35: =A35 -> 1 | AJ35: =H35 -> 78908.489 | AK35: =S35 -> 78908.489 | AL35: =AF35 -> 78908.489 | AM35: =A35 -> 1 | AN35: =I35 -> 2451.511 | AO35: =T35 -> 2451.511 | AP35: =AE35 -> 2451.511
A36: =A35+1 -> 2 | B36: =H35 -> 78908.489 | C36: =IF(OR(B36<=0,A36>Financiamento_EV!$C$7),0,B36*Financiamento_EV!$C$9) -> 0 | D36: =MAX(0,B36+C36) -> 78908.489 | E36: =IF(D36<=0,0,D36*Financiamento_EV!$C$6) -> 1341.4443 | F36: =IF(D36<=0,0,IF(Financiamento_EV!$C$6=0,D36/(Financiamento_EV!$C$7-A36+1),D36*Financiamento_EV!$C$6/(1-(1+Financiamento_EV!$C$6)^(-(Financiamento_EV!$C$7-A36+1))))) -> 2451.511 | G36: =MAX(0,MIN(D36,F36-E36)) -> 1110.0666 | H36: =MAX(0,D36-G36) -> 77798.422 | I36: =IF(D36<=0,0,F36) -> 2451.511 | K36: =K35+1 -> 2 | L36: =S35 -> 78908.489 | M36: =IF(OR(L36<=0,K36>Financiamento_EV!$C$7),0,L36*Financiamento_EV!$C$9) -> 0 | N36: =MAX(0,L36+M36) -> 78908.489 | O36: =IF(N36<=0,0,N36*Financiamento_EV!$C$6) -> 1341.4443 | P36: =IF(N36<=0,0,IF(Financiamento_EV!$C$6=0,N36/(Financiamento_EV!$C$7-K36+1),N36*Financiamento_EV!$C$6/(1-(1+Financiamento_EV!$C$6)^(-(Financiamento_EV!$C$7-K36+1))))) -> 2451.511 | Q36: =MAX(0,MIN(N36,P36-O36)) -> 1110.0666 | R36: =IF(N36<=0,0,MIN(IF(ISNUMBER(INDEX(Financiamento_EV!$I$17:$I$136,K36)),MAX(0,INDEX(Financiamento_EV!$I$17:$I$136,K36)),IF(K36>=Financiamento_EV!$C$11,Financiamento_EV!$C$10,0)),MAX(0,N36-Q36))) -> 0 | S36: =MAX(0,N36-Q36-R36) -> 77798.422 | T36: =IF(N36<=0,0,P36+R36) -> 2451.511 | V36: =V35+1 -> 2 | W36: =AF35 -> 78908.489 | X36: =IF(OR(W36<=0,V36>Financiamento_EV!$C$7),0,W36*Financiamento_EV!$C$9) -> 0 | Y36: =MAX(0,W36+X36) -> 78908.489 | Z36: =IF(Y36<=0,0,Y36*Financiamento_EV!$C$6) -> 1341.4443 | AA36: =IF(Y36<=0,0,IF(Financiamento_EV!$C$6=0,Y36/(Financiamento_EV!$C$7-V36+1),Y36*Financiamento_EV!$C$6/(1-(1+Financiamento_EV!$C$6)^(-(Financiamento_EV!$C$7-V36+1))))) -> 2451.511 | AB36: =MAX(0,MIN(Y36,AA36-Z36)) -> 1110.0666 | AC36: =IF(Y36<=0,0,MIN(IF(ISNUMBER(INDEX(Financiamento_EV!$I$17:$I$136,V36)),MAX(0,INDEX(Financiamento_EV!$I$17:$I$136,V36)),IF(V36>=Financiamento_EV!$C$11,Financiamento_EV!$C$10,0)),MAX(0,Y36-AB36))) -> 0 | AD36: =IF(OR(Y36<=0,V36<Financiamento_EV!$C$11),0,MIN(MAX(0,Financiamento_EV!$F$5-AA36),MAX(0,Y36-AB36-AC36))) -> 0 | AE36: =IF(Y36<=0,0,AA36+AC36+AD36) -> 2451.511 | AF36: =MAX(0,Y36-AB36-AC36-AD36) -> 77798.422 | AG36: =AC36+AD36 -> 0 | AI36: =A36 -> 2 | AJ36: =H36 -> 77798.422 | AK36: =S36 -> 77798.422 | AL36: =AF36 -> 77798.422 | AM36: =A36 -> 2 | AN36: =I36 -> 2451.511 | AO36: =T36 -> 2451.511 | AP36: =AE36 -> 2451.511
A37: =A36+1 -> 3 | B37: =H36 -> 77798.422 | C37: =IF(OR(B37<=0,A37>Financiamento_EV!$C$7),0,B37*Financiamento_EV!$C$9) -> 0 | D37: =MAX(0,B37+C37) -> 77798.422 | E37: =IF(D37<=0,0,D37*Financiamento_EV!$C$6) -> 1322.5732 | F37: =IF(D37<=0,0,IF(Financiamento_EV!$C$6=0,D37/(Financiamento_EV!$C$7-A37+1),D37*Financiamento_EV!$C$6/(1-(1+Financiamento_EV!$C$6)^(-(Financiamento_EV!$C$7-A37+1))))) -> 2451.511 | G37: =MAX(0,MIN(D37,F37-E37)) -> 1128.9378 | H37: =MAX(0,D37-G37) -> 76669.485 | I37: =IF(D37<=0,0,F37) -> 2451.511 | K37: =K36+1 -> 3 | L37: =S36 -> 77798.422 | M37: =IF(OR(L37<=0,K37>Financiamento_EV!$C$7),0,L37*Financiamento_EV!$C$9) -> 0 | N37: =MAX(0,L37+M37) -> 77798.422 | O37: =IF(N37<=0,0,N37*Financiamento_EV!$C$6) -> 1322.5732 | P37: =IF(N37<=0,0,IF(Financiamento_EV!$C$6=0,N37/(Financiamento_EV!$C$7-K37+1),N37*Financiamento_EV!$C$6/(1-(1+Financiamento_EV!$C$6)^(-(Financiamento_EV!$C$7-K37+1))))) -> 2451.511 | Q37: =MAX(0,MIN(N37,P37-O37)) -> 1128.9378 | R37: =IF(N37<=0,0,MIN(IF(ISNUMBER(INDEX(Financiamento_EV!$I$17:$I$136,K37)),MAX(0,INDEX(Financiamento_EV!$I$17:$I$136,K37)),IF(K37>=Financiamento_EV!$C$11,Financiamento_EV!$C$10,0)),MAX(0,N37-Q37))) -> 0 | S37: =MAX(0,N37-Q37-R37) -> 76669.485 | T37: =IF(N37<=0,0,P37+R37) -> 2451.511 | V37: =V36+1 -> 3 | W37: =AF36 -> 77798.422 | X37: =IF(OR(W37<=0,V37>Financiamento_EV!$C$7),0,W37*Financiamento_EV!$C$9) -> 0 | Y37: =MAX(0,W37+X37) -> 77798.422 | Z37: =IF(Y37<=0,0,Y37*Financiamento_EV!$C$6) -> 1322.5732 | AA37: =IF(Y37<=0,0,IF(Financiamento_EV!$C$6=0,Y37/(Financiamento_EV!$C$7-V37+1),Y37*Financiamento_EV!$C$6/(1-(1+Financiamento_EV!$C$6)^(-(Financiamento_EV!$C$7-V37+1))))) -> 2451.511 | AB37: =MAX(0,MIN(Y37,AA37-Z37)) -> 1128.9378 | AC37: =IF(Y37<=0,0,MIN(IF(ISNUMBER(INDEX(Financiamento_EV!$I$17:$I$136,V37)),MAX(0,INDEX(Financiamento_EV!$I$17:$I$136,V37)),IF(V37>=Financiamento_EV!$C$11,Financiamento_EV!$C$10,0)),MAX(0,Y37-AB37))) -> 0 | AD37: =IF(OR(Y37<=0,V37<Financiamento_EV!$C$11),0,MIN(MAX(0,Financiamento_EV!$F$5-AA37),MAX(0,Y37-AB37-AC37))) -> 9.094947e-13 | AE37: =IF(Y37<=0,0,AA37+AC37+AD37) -> 2451.511 | AF37: =MAX(0,Y37-AB37-AC37-AD37) -> 76669.485 | AG37: =AC37+AD37 -> 9.094947e-13 | AI37: =A37 -> 3 | AJ37: =H37 -> 76669.485 | AK37: =S37 -> 76669.485 | AL37: =AF37 -> 76669.485 | AM37: =A37 -> 3 | AN37: =I37 -> 2451.511 | AO37: =T37 -> 2451.511 | AP37: =AE37 -> 2451.511
A38: =A37+1 -> 4 | B38: =H37 -> 76669.485 | C38: =IF(OR(B38<=0,A38>Financiamento_EV!$C$7),0,B38*Financiamento_EV!$C$9) -> 0 | D38: =MAX(0,B38+C38) -> 76669.485 | E38: =IF(D38<=0,0,D38*Financiamento_EV!$C$6) -> 1303.3812 | F38: =IF(D38<=0,0,IF(Financiamento_EV!$C$6=0,D38/(Financiamento_EV!$C$7-A38+1),D38*Financiamento_EV!$C$6/(1-(1+Financiamento_EV!$C$6)^(-(Financiamento_EV!$C$7-A38+1))))) -> 2451.511 | G38: =MAX(0,MIN(D38,F38-E38)) -> 1148.1297 | H38: =MAX(0,D38-G38) -> 75521.355 | I38: =IF(D38<=0,0,F38) -> 2451.511 | K38: =K37+1 -> 4 | L38: =S37 -> 76669.485 | M38: =IF(OR(L38<=0,K38>Financiamento_EV!$C$7),0,L38*Financiamento_EV!$C$9) -> 0 | N38: =MAX(0,L38+M38) -> 76669.485 | O38: =IF(N38<=0,0,N38*Financiamento_EV!$C$6) -> 1303.3812 | P38: =IF(N38<=0,0,IF(Financiamento_EV!$C$6=0,N38/(Financiamento_EV!$C$7-K38+1),N38*Financiamento_EV!$C$6/(1-(1+Financiamento_EV!$C$6)^(-(Financiamento_EV!$C$7-K38+1))))) -> 2451.511 | Q38: =MAX(0,MIN(N38,P38-O38)) -> 1148.1297 | R38: =IF(N38<=0,0,MIN(IF(ISNUMBER(INDEX(Financiamento_EV!$I$17:$I$136,K38)),MAX(0,INDEX(Financiamento_EV!$I$17:$I$136,K38)),IF(K38>=Financiamento_EV!$C$11,Financiamento_EV!$C$10,0)),MAX(0,N38-Q38))) -> 0 | S38: =MAX(0,N38-Q38-R38) -> 75521.355 | T38: =IF(N38<=0,0,P38+R38) -> 2451.511 | V38: =V37+1 -> 4 | W38: =AF37 -> 76669.485 | X38: =IF(OR(W38<=0,V38>Financiamento_EV!$C$7),0,W38*Financiamento_EV!$C$9) -> 0 | Y38: =MAX(0,W38+X38) -> 76669.485 | Z38: =IF(Y38<=0,0,Y38*Financiamento_EV!$C$6) -> 1303.3812 | AA38: =IF(Y38<=0,0,IF(Financiamento_EV!$C$6=0,Y38/(Financiamento_EV!$C$7-V38+1),Y38*Financiamento_EV!$C$6/(1-(1+Financiamento_EV!$C$6)^(-(Financiamento_EV!$C$7-V38+1))))) -> 2451.511 | AB38: =MAX(0,MIN(Y38,AA38-Z38)) -> 1148.1297 | AC38: =IF(Y38<=0,0,MIN(IF(ISNUMBER(INDEX(Financiamento_EV!$I$17:$I$136,V38)),MAX(0,INDEX(Financiamento_EV!$I$17:$I$136,V38)),IF(V38>=Financiamento_EV!$C$11,Financiamento_EV!$C$10,0)),MAX(0,Y38-AB38))) -> 0 | AD38: =IF(OR(Y38<=0,V38<Financiamento_EV!$C$11),0,MIN(MAX(0,Financiamento_EV!$F$5-AA38),MAX(0,Y38-AB38-AC38))) -> 4.5474735e-13 | AE38: =IF(Y38<=0,0,AA38+AC38+AD38) -> 2451.511 | AF38: =MAX(0,Y38-AB38-AC38-AD38) -> 75521.355 | AG38: =AC38+AD38 -> 4.5474735e-13 | AI38: =A38 -> 4 | AJ38: =H38 -> 75521.355 | AK38: =S38 -> 75521.355 | AL38: =AF38 -> 75521.355 | AM38: =A38 -> 4 | AN38: =I38 -> 2451.511 | AO38: =T38 -> 2451.511 | AP38: =AE38 -> 2451.511
A39: =A38+1 -> 5 | B39: =H38 -> 75521.355 | C39: =IF(OR(B39<=0,A39>Financiamento_EV!$C$7),0,B39*Financiamento_EV!$C$9) -> 0 | D39: =MAX(0,B39+C39) -> 75521.355 | E39: =IF(D39<=0,0,D39*Financiamento_EV!$C$6) -> 1283.863 | F39: =IF(D39<=0,0,IF(Financiamento_EV!$C$6=0,D39/(Financiamento_EV!$C$7-A39+1),D39*Financiamento_EV!$C$6/(1-(1+Financiamento_EV!$C$6)^(-(Financiamento_EV!$C$7-A39+1))))) -> 2451.511 | G39: =MAX(0,MIN(D39,F39-E39)) -> 1167.6479 | H39: =MAX(0,D39-G39) -> 74353.707 | I39: =IF(D39<=0,0,F39) -> 2451.511 | K39: =K38+1 -> 5 | L39: =S38 -> 75521.355 | M39: =IF(OR(L39<=0,K39>Financiamento_EV!$C$7),0,L39*Financiamento_EV!$C$9) -> 0 | N39: =MAX(0,L39+M39) -> 75521.355 | O39: =IF(N39<=0,0,N39*Financiamento_EV!$C$6) -> 1283.863 | P39: =IF(N39<=0,0,IF(Financiamento_EV!$C$6=0,N39/(Financiamento_EV!$C$7-K39+1),N39*Financiamento_EV!$C$6/(1-(1+Financiamento_EV!$C$6)^(-(Financiamento_EV!$C$7-K39+1))))) -> 2451.511 | Q39: =MAX(0,MIN(N39,P39-O39)) -> 1167.6479 | R39: =IF(N39<=0,0,MIN(IF(ISNUMBER(INDEX(Financiamento_EV!$I$17:$I$136,K39)),MAX(0,INDEX(Financiamento_EV!$I$17:$I$136,K39)),IF(K39>=Financiamento_EV!$C$11,Financiamento_EV!$C$10,0)),MAX(0,N39-Q39))) -> 0 | S39: =MAX(0,N39-Q39-R39) -> 74353.707 | T39: =IF(N39<=0,0,P39+R39) -> 2451.511 | V39: =V38+1 -> 5 | W39: =AF38 -> 75521.355 | X39: =IF(OR(W39<=0,V39>Financiamento_EV!$C$7),0,W39*Financiamento_EV!$C$9) -> 0 | Y39: =MAX(0,W39+X39) -> 75521.355 | Z39: =IF(Y39<=0,0,Y39*Financiamento_EV!$C$6) -> 1283.863 | AA39: =IF(Y39<=0,0,IF(Financiamento_EV!$C$6=0,Y39/(Financiamento_EV!$C$7-V39+1),Y39*Financiamento_EV!$C$6/(1-(1+Financiamento_EV!$C$6)^(-(Financiamento_EV!$C$7-V39+1))))) -> 2451.511 | AB39: =MAX(0,MIN(Y39,AA39-Z39)) -> 1167.6479 | AC39: =IF(Y39<=0,0,MIN(IF(ISNUMBER(INDEX(Financiamento_EV!$I$17:$I$136,V39)),MAX(0,INDEX(Financiamento_EV!$I$17:$I$136,V39)),IF(V39>=Financiamento_EV!$C$11,Financiamento_EV!$C$10,0)),MAX(0,Y39-AB39))) -> 0 | AD39: =IF(OR(Y39<=0,V39<Financiamento_EV!$C$11),0,MIN(MAX(0,Financiamento_EV!$F$5-AA39),MAX(0,Y39-AB39-AC39))) -> 9.094947e-13 | AE39: =IF(Y39<=0,0,AA39+AC39+AD39) -> 2451.511 | AF39: =MAX(0,Y39-AB39-AC39-AD39) -> 74353.707 | AG39: =AC39+AD39 -> 9.094947e-13 | AI39: =A39 -> 5 | AJ39: =H39 -> 74353.707 | AK39: =S39 -> 74353.707 | AL39: =AF39 -> 74353.707 | AM39: =A39 -> 5 | AN39: =I39 -> 2451.511 | AO39: =T39 -> 2451.511 | AP39: =AE39 -> 2451.511
A40: =A39+1 -> 6 | B40: =H39 -> 74353.707 | C40: =IF(OR(B40<=0,A40>Financiamento_EV!$C$7),0,B40*Financiamento_EV!$C$9) -> 0 | D40: =MAX(0,B40+C40) -> 74353.707 | E40: =IF(D40<=0,0,D40*Financiamento_EV!$C$6) -> 1264.013 | F40: =IF(D40<=0,0,IF(Financiamento_EV!$C$6=0,D40/(Financiamento_EV!$C$7-A40+1),D40*Financiamento_EV!$C$6/(1-(1+Financiamento_EV!$C$6)^(-(Financiamento_EV!$C$7-A40+1))))) -> 2451.511 | G40: =MAX(0,MIN(D40,F40-E40)) -> 1187.4979 | H40: =MAX(0,D40-G40) -> 73166.209 | I40: =IF(D40<=0,0,F40) -> 2451.511 | K40: =K39+1 -> 6 | L40: =S39 -> 74353.707 | M40: =IF(OR(L40<=0,K40>Financiamento_EV!$C$7),0,L40*Financiamento_EV!$C$9) -> 0 | N40: =MAX(0,L40+M40) -> 74353.707 | O40: =IF(N40<=0,0,N40*Financiamento_EV!$C$6) -> 1264.013 | P40: =IF(N40<=0,0,IF(Financiamento_EV!$C$6=0,N40/(Financiamento_EV!$C$7-K40+1),N40*Financiamento_EV!$C$6/(1-(1+Financiamento_EV!$C$6)^(-(Financiamento_EV!$C$7-K40+1))))) -> 2451.511 | Q40: =MAX(0,MIN(N40,P40-O40)) -> 1187.4979 | R40: =IF(N40<=0,0,MIN(IF(ISNUMBER(INDEX(Financiamento_EV!$I$17:$I$136,K40)),MAX(0,INDEX(Financiamento_EV!$I$17:$I$136,K40)),IF(K40>=Financiamento_EV!$C$11,Financiamento_EV!$C$10,0)),MAX(0,N40-Q40))) -> 0 | S40: =MAX(0,N40-Q40-R40) -> 73166.209 | T40: =IF(N40<=0,0,P40+R40) -> 2451.511 | V40: =V39+1 -> 6 | W40: =AF39 -> 74353.707 | X40: =IF(OR(W40<=0,V40>Financiamento_EV!$C$7),0,W40*Financiamento_EV!$C$9) -> 0 | Y40: =MAX(0,W40+X40) -> 74353.707 | Z40: =IF(Y40<=0,0,Y40*Financiamento_EV!$C$6) -> 1264.013 | AA40: =IF(Y40<=0,0,IF(Financiamento_EV!$C$6=0,Y40/(Financiamento_EV!$C$7-V40+1),Y40*Financiamento_EV!$C$6/(1-(1+Financiamento_EV!$C$6)^(-(Financiamento_EV!$C$7-V40+1))))) -> 2451.511 | AB40: =MAX(0,MIN(Y40,AA40-Z40)) -> 1187.4979 | AC40: =IF(Y40<=0,0,MIN(IF(ISNUMBER(INDEX(Financiamento_EV!$I$17:$I$136,V40)),MAX(0,INDEX(Financiamento_EV!$I$17:$I$136,V40)),IF(V40>=Financiamento_EV!$C$11,Financiamento_EV!$C$10,0)),MAX(0,Y40-AB40))) -> 0 | AD40: =IF(OR(Y40<=0,V40<Financiamento_EV!$C$11),0,MIN(MAX(0,Financiamento_EV!$F$5-AA40),MAX(0,Y40-AB40-AC40))) -> 9.094947e-13 | AE40: =IF(Y40<=0,0,AA40+AC40+AD40) -> 2451.511 | AF40: =MAX(0,Y40-AB40-AC40-AD40) -> 73166.209 | AG40: =AC40+AD40 -> 9.094947e-13 | AI40: =A40 -> 6 | AJ40: =H40 -> 73166.209 | AK40: =S40 -> 73166.209 | AL40: =AF40 -> 73166.209 | AM40: =A40 -> 6 | AN40: =I40 -> 2451.511 | AO40: =T40 -> 2451.511 | AP40: =AE40 -> 2451.511
A41: =A40+1 -> 7 | B41: =H40 -> 73166.209 | C41: =IF(OR(B41<=0,A41>Financiamento_EV!$C$7),0,B41*Financiamento_EV!$C$9) -> 0 | D41: =MAX(0,B41+C41) -> 73166.209 | E41: =IF(D41<=0,0,D41*Financiamento_EV!$C$6) -> 1243.8256 | F41: =IF(D41<=0,0,IF(Financiamento_EV!$C$6=0,D41/(Financiamento_EV!$C$7-A41+1),D41*Financiamento_EV!$C$6/(1-(1+Financiamento_EV!$C$6)^(-(Financiamento_EV!$C$7-A41+1))))) -> 2451.511 | G41: =MAX(0,MIN(D41,F41-E41)) -> 1207.6854 | H41: =MAX(0,D41-G41) -> 71958.524 | I41: =IF(D41<=0,0,F41) -> 2451.511 | K41: =K40+1 -> 7 | L41: =S40 -> 73166.209 | M41: =IF(OR(L41<=0,K41>Financiamento_EV!$C$7),0,L41*Financiamento_EV!$C$9) -> 0 | N41: =MAX(0,L41+M41) -> 73166.209 | O41: =IF(N41<=0,0,N41*Financiamento_EV!$C$6) -> 1243.8256 | P41: =IF(N41<=0,0,IF(Financiamento_EV!$C$6=0,N41/(Financiamento_EV!$C$7-K41+1),N41*Financiamento_EV!$C$6/(1-(1+Financiamento_EV!$C$6)^(-(Financiamento_EV!$C$7-K41+1))))) -> 2451.511 | Q41: =MAX(0,MIN(N41,P41-O41)) -> 1207.6854 | R41: =IF(N41<=0,0,MIN(IF(ISNUMBER(INDEX(Financiamento_EV!$I$17:$I$136,K41)),MAX(0,INDEX(Financiamento_EV!$I$17:$I$136,K41)),IF(K41>=Financiamento_EV!$C$11,Financiamento_EV!$C$10,0)),MAX(0,N41-Q41))) -> 0 | S41: =MAX(0,N41-Q41-R41) -> 71958.524 | T41: =IF(N41<=0,0,P41+R41) -> 2451.511 | V41: =V40+1 -> 7 | W41: =AF40 -> 73166.209 | X41: =IF(OR(W41<=0,V41>Financiamento_EV!$C$7),0,W41*Financiamento_EV!$C$9) -> 0 | Y41: =MAX(0,W41+X41) -> 73166.209 | Z41: =IF(Y41<=0,0,Y41*Financiamento_EV!$C$6) -> 1243.8256 | AA41: =IF(Y41<=0,0,IF(Financiamento_EV!$C$6=0,Y41/(Financiamento_EV!$C$7-V41+1),Y41*Financiamento_EV!$C$6/(1-(1+Financiamento_EV!$C$6)^(-(Financiamento_EV!$C$7-V41+1))))) -> 2451.511 | AB41: =MAX(0,MIN(Y41,AA41-Z41)) -> 1207.6854 | AC41: =IF(Y41<=0,0,MIN(IF(ISNUMBER(INDEX(Financiamento_EV!$I$17:$I$136,V41)),MAX(0,INDEX(Financiamento_EV!$I$17:$I$136,V41)),IF(V41>=Financiamento_EV!$C$11,Financiamento_EV!$C$10,0)),MAX(0,Y41-AB41))) -> 0 | AD41: =IF(OR(Y41<=0,V41<Financiamento_EV!$C$11),0,MIN(MAX(0,Financiamento_EV!$F$5-AA41),MAX(0,Y41-AB41-AC41))) -> 9.094947e-13 | AE41: =IF(Y41<=0,0,AA41+AC41+AD41) -> 2451.511 | AF41: =MAX(0,Y41-AB41-AC41-AD41) -> 71958.524 | AG41: =AC41+AD41 -> 9.094947e-13 | AI41: =A41 -> 7 | AJ41: =H41 -> 71958.524 | AK41: =S41 -> 71958.524 | AL41: =AF41 -> 71958.524 | AM41: =A41 -> 7 | AN41: =I41 -> 2451.511 | AO41: =T41 -> 2451.511 | AP41: =AE41 -> 2451.511
A42: =A41+1 -> 8 | B42: =H41 -> 71958.524 | C42: =IF(OR(B42<=0,A42>Financiamento_EV!$C$7),0,B42*Financiamento_EV!$C$9) -> 0 | D42: =MAX(0,B42+C42) -> 71958.524 | E42: =IF(D42<=0,0,D42*Financiamento_EV!$C$6) -> 1223.2949 | F42: =IF(D42<=0,0,IF(Financiamento_EV!$C$6=0,D42/(Financiamento_EV!$C$7-A42+1),D42*Financiamento_EV!$C$6/(1-(1+Financiamento_EV!$C$6)^(-(Financiamento_EV!$C$7-A42+1))))) -> 2451.511 | G42: =MAX(0,MIN(D42,F42-E42)) -> 1228.216 | H42: =MAX(0,D42-G42) -> 70730.308 | I42: =IF(D42<=0,0,F42) -> 2451.511 | K42: =K41+1 -> 8 | L42: =S41 -> 71958.524 | M42: =IF(OR(L42<=0,K42>Financiamento_EV!$C$7),0,L42*Financiamento_EV!$C$9) -> 0 | N42: =MAX(0,L42+M42) -> 71958.524 | O42: =IF(N42<=0,0,N42*Financiamento_EV!$C$6) -> 1223.2949 | P42: =IF(N42<=0,0,IF(Financiamento_EV!$C$6=0,N42/(Financiamento_EV!$C$7-K42+1),N42*Financiamento_EV!$C$6/(1-(1+Financiamento_EV!$C$6)^(-(Financiamento_EV!$C$7-K42+1))))) -> 2451.511 | Q42: =MAX(0,MIN(N42,P42-O42)) -> 1228.216 | R42: =IF(N42<=0,0,MIN(IF(ISNUMBER(INDEX(Financiamento_EV!$I$17:$I$136,K42)),MAX(0,INDEX(Financiamento_EV!$I$17:$I$136,K42)),IF(K42>=Financiamento_EV!$C$11,Financiamento_EV!$C$10,0)),MAX(0,N42-Q42))) -> 0 | S42: =MAX(0,N42-Q42-R42) -> 70730.308 | T42: =IF(N42<=0,0,P42+R42) -> 2451.511 | V42: =V41+1 -> 8 | W42: =AF41 -> 71958.524 | X42: =IF(OR(W42<=0,V42>Financiamento_EV!$C$7),0,W42*Financiamento_EV!$C$9) -> 0 | Y42: =MAX(0,W42+X42) -> 71958.524 | Z42: =IF(Y42<=0,0,Y42*Financiamento_EV!$C$6) -> 1223.2949 | AA42: =IF(Y42<=0,0,IF(Financiamento_EV!$C$6=0,Y42/(Financiamento_EV!$C$7-V42+1),Y42*Financiamento_EV!$C$6/(1-(1+Financiamento_EV!$C$6)^(-(Financiamento_EV!$C$7-V42+1))))) -> 2451.511 | AB42: =MAX(0,MIN(Y42,AA42-Z42)) -> 1228.216 | AC42: =IF(Y42<=0,0,MIN(IF(ISNUMBER(INDEX(Financiamento_EV!$I$17:$I$136,V42)),MAX(0,INDEX(Financiamento_EV!$I$17:$I$136,V42)),IF(V42>=Financiamento_EV!$C$11,Financiamento_EV!$C$10,0)),MAX(0,Y42-AB42))) -> 0 | AD42: =IF(OR(Y42<=0,V42<Financiamento_EV!$C$11),0,MIN(MAX(0,Financiamento_EV!$F$5-AA42),MAX(0,Y42-AB42-AC42))) -> 9.094947e-13 | AE42: =IF(Y42<=0,0,AA42+AC42+AD42) -> 2451.511 | AF42: =MAX(0,Y42-AB42-AC42-AD42) -> 70730.308 | AG42: =AC42+AD42 -> 9.094947e-13 | AI42: =A42 -> 8 | AJ42: =H42 -> 70730.308 | AK42: =S42 -> 70730.308 | AL42: =AF42 -> 70730.308 | AM42: =A42 -> 8 | AN42: =I42 -> 2451.511 | AO42: =T42 -> 2451.511 | AP42: =AE42 -> 2451.511
A43: =A42+1 -> 9 | B43: =H42 -> 70730.308 | C43: =IF(OR(B43<=0,A43>Financiamento_EV!$C$7),0,B43*Financiamento_EV!$C$9) -> 0 | D43: =MAX(0,B43+C43) -> 70730.308 | E43: =IF(D43<=0,0,D43*Financiamento_EV!$C$6) -> 1202.4152 | F43: =IF(D43<=0,0,IF(Financiamento_EV!$C$6=0,D43/(Financiamento_EV!$C$7-A43+1),D43*Financiamento_EV!$C$6/(1-(1+Financiamento_EV!$C$6)^(-(Financiamento_EV!$C$7-A43+1))))) -> 2451.511 | G43: =MAX(0,MIN(D43,F43-E43)) -> 1249.0957 | H43: =MAX(0,D43-G43) -> 69481.212 | I43: =IF(D43<=0,0,F43) -> 2451.511 | K43: =K42+1 -> 9 | L43: =S42 -> 70730.308 | M43: =IF(OR(L43<=0,K43>Financiamento_EV!$C$7),0,L43*Financiamento_EV!$C$9) -> 0 | N43: =MAX(0,L43+M43) -> 70730.308 | O43: =IF(N43<=0,0,N43*Financiamento_EV!$C$6) -> 1202.4152 | P43: =IF(N43<=0,0,IF(Financiamento_EV!$C$6=0,N43/(Financiamento_EV!$C$7-K43+1),N43*Financiamento_EV!$C$6/(1-(1+Financiamento_EV!$C$6)^(-(Financiamento_EV!$C$7-K43+1))))) -> 2451.511 | Q43: =MAX(0,MIN(N43,P43-O43)) -> 1249.0957 | R43: =IF(N43<=0,0,MIN(IF(ISNUMBER(INDEX(Financiamento_EV!$I$17:$I$136,K43)),MAX(0,INDEX(Financiamento_EV!$I$17:$I$136,K43)),IF(K43>=Financiamento_EV!$C$11,Financiamento_EV!$C$10,0)),MAX(0,N43-Q43))) -> 0 | S43: =MAX(0,N43-Q43-R43) -> 69481.212 | T43: =IF(N43<=0,0,P43+R43) -> 2451.511 | V43: =V42+1 -> 9 | W43: =AF42 -> 70730.308 | X43: =IF(OR(W43<=0,V43>Financiamento_EV!$C$7),0,W43*Financiamento_EV!$C$9) -> 0 | Y43: =MAX(0,W43+X43) -> 70730.308 | Z43: =IF(Y43<=0,0,Y43*Financiamento_EV!$C$6) -> 1202.4152 | AA43: =IF(Y43<=0,0,IF(Financiamento_EV!$C$6=0,Y43/(Financiamento_EV!$C$7-V43+1),Y43*Financiamento_EV!$C$6/(1-(1+Financiamento_EV!$C$6)^(-(Financiamento_EV!$C$7-V43+1))))) -> 2451.511 | AB43: =MAX(0,MIN(Y43,AA43-Z43)) -> 1249.0957 | AC43: =IF(Y43<=0,0,MIN(IF(ISNUMBER(INDEX(Financiamento_EV!$I$17:$I$136,V43)),MAX(0,INDEX(Financiamento_EV!$I$17:$I$136,V43)),IF(V43>=Financiamento_EV!$C$11,Financiamento_EV!$C$10,0)),MAX(0,Y43-AB43))) -> 0 | AD43: =IF(OR(Y43<=0,V43<Financiamento_EV!$C$11),0,MIN(MAX(0,Financiamento_EV!$F$5-AA43),MAX(0,Y43-AB43-AC43))) -> 1.3642421e-12 | AE43: =IF(Y43<=0,0,AA43+AC43+AD43) -> 2451.511 | AF43: =MAX(0,Y43-AB43-AC43-AD43) -> 69481.212 | AG43: =AC43+AD43 -> 1.3642421e-12 | AI43: =A43 -> 9 | AJ43: =H43 -> 69481.212 | AK43: =S43 -> 69481.212 | AL43: =AF43 -> 69481.212 | AM43: =A43 -> 9 | AN43: =I43 -> 2451.511 | AO43: =T43 -> 2451.511 | AP43: =AE43 -> 2451.511
A44: =A43+1 -> 10 | B44: =H43 -> 69481.212 | C44: =IF(OR(B44<=0,A44>Financiamento_EV!$C$7),0,B44*Financiamento_EV!$C$9) -> 0 | D44: =MAX(0,B44+C44) -> 69481.212 | E44: =IF(D44<=0,0,D44*Financiamento_EV!$C$6) -> 1181.1806 | F44: =IF(D44<=0,0,IF(Financiamento_EV!$C$6=0,D44/(Financiamento_EV!$C$7-A44+1),D44*Financiamento_EV!$C$6/(1-(1+Financiamento_EV!$C$6)^(-(Financiamento_EV!$C$7-A44+1))))) -> 2451.511 | G44: =MAX(0,MIN(D44,F44-E44)) -> 1270.3303 | H44: =MAX(0,D44-G44) -> 68210.882 | I44: =IF(D44<=0,0,F44) -> 2451.511 | K44: =K43+1 -> 10 | L44: =S43 -> 69481.212 | M44: =IF(OR(L44<=0,K44>Financiamento_EV!$C$7),0,L44*Financiamento_EV!$C$9) -> 0 | N44: =MAX(0,L44+M44) -> 69481.212 | O44: =IF(N44<=0,0,N44*Financiamento_EV!$C$6) -> 1181.1806 | P44: =IF(N44<=0,0,IF(Financiamento_EV!$C$6=0,N44/(Financiamento_EV!$C$7-K44+1),N44*Financiamento_EV!$C$6/(1-(1+Financiamento_EV!$C$6)^(-(Financiamento_EV!$C$7-K44+1))))) -> 2451.511 | Q44: =MAX(0,MIN(N44,P44-O44)) -> 1270.3303 | R44: =IF(N44<=0,0,MIN(IF(ISNUMBER(INDEX(Financiamento_EV!$I$17:$I$136,K44)),MAX(0,INDEX(Financiamento_EV!$I$17:$I$136,K44)),IF(K44>=Financiamento_EV!$C$11,Financiamento_EV!$C$10,0)),MAX(0,N44-Q44))) -> 0 | S44: =MAX(0,N44-Q44-R44) -> 68210.882 | T44: =IF(N44<=0,0,P44+R44) -> 2451.511 | V44: =V43+1 -> 10 | W44: =AF43 -> 69481.212 | X44: =IF(OR(W44<=0,V44>Financiamento_EV!$C$7),0,W44*Financiamento_EV!$C$9) -> 0 | Y44: =MAX(0,W44+X44) -> 69481.212 | Z44: =IF(Y44<=0,0,Y44*Financiamento_EV!$C$6) -> 1181.1806 | AA44: =IF(Y44<=0,0,IF(Financiamento_EV!$C$6=0,Y44/(Financiamento_EV!$C$7-V44+1),Y44*Financiamento_EV!$C$6/(1-(1+Financiamento_EV!$C$6)^(-(Financiamento_EV!$C$7-V44+1))))) -> 2451.511 | AB44: =MAX(0,MIN(Y44,AA44-Z44)) -> 1270.3303 | AC44: =IF(Y44<=0,0,MIN(IF(ISNUMBER(INDEX(Financiamento_EV!$I$17:$I$136,V44)),MAX(0,INDEX(Financiamento_EV!$I$17:$I$136,V44)),IF(V44>=Financiamento_EV!$C$11,Financiamento_EV!$C$10,0)),MAX(0,Y44-AB44))) -> 0 | AD44: =IF(OR(Y44<=0,V44<Financiamento_EV!$C$11),0,MIN(MAX(0,Financiamento_EV!$F$5-AA44),MAX(0,Y44-AB44-AC44))) -> 1.3642421e-12 | AE44: =IF(Y44<=0,0,AA44+AC44+AD44) -> 2451.511 | AF44: =MAX(0,Y44-AB44-AC44-AD44) -> 68210.882 | AG44: =AC44+AD44 -> 1.3642421e-12 | AI44: =A44 -> 10 | AJ44: =H44 -> 68210.882 | AK44: =S44 -> 68210.882 | AL44: =AF44 -> 68210.882 | AM44: =A44 -> 10 | AN44: =I44 -> 2451.511 | AO44: =T44 -> 2451.511 | AP44: =AE44 -> 2451.511
A45: =A44+1 -> 11 | B45: =H44 -> 68210.882 | C45: =IF(OR(B45<=0,A45>Financiamento_EV!$C$7),0,B45*Financiamento_EV!$C$9) -> 0 | D45: =MAX(0,B45+C45) -> 68210.882 | E45: =IF(D45<=0,0,D45*Financiamento_EV!$C$6) -> 1159.585 | F45: =IF(D45<=0,0,IF(Financiamento_EV!$C$6=0,D45/(Financiamento_EV!$C$7-A45+1),D45*Financiamento_EV!$C$6/(1-(1+Financiamento_EV!$C$6)^(-(Financiamento_EV!$C$7-A45+1))))) -> 2451.511 | G45: =MAX(0,MIN(D45,F45-E45)) -> 1291.926 | H45: =MAX(0,D45-G45) -> 66918.956 | I45: =IF(D45<=0,0,F45) -> 2451.511 | K45: =K44+1 -> 11 | L45: =S44 -> 68210.882 | M45: =IF(OR(L45<=0,K45>Financiamento_EV!$C$7),0,L45*Financiamento_EV!$C$9) -> 0 | N45: =MAX(0,L45+M45) -> 68210.882 | O45: =IF(N45<=0,0,N45*Financiamento_EV!$C$6) -> 1159.585 | P45: =IF(N45<=0,0,IF(Financiamento_EV!$C$6=0,N45/(Financiamento_EV!$C$7-K45+1),N45*Financiamento_EV!$C$6/(1-(1+Financiamento_EV!$C$6)^(-(Financiamento_EV!$C$7-K45+1))))) -> 2451.511 | Q45: =MAX(0,MIN(N45,P45-O45)) -> 1291.926 | R45: =IF(N45<=0,0,MIN(IF(ISNUMBER(INDEX(Financiamento_EV!$I$17:$I$136,K45)),MAX(0,INDEX(Financiamento_EV!$I$17:$I$136,K45)),IF(K45>=Financiamento_EV!$C$11,Financiamento_EV!$C$10,0)),MAX(0,N45-Q45))) -> 0 | S45: =MAX(0,N45-Q45-R45) -> 66918.956 | T45: =IF(N45<=0,0,P45+R45) -> 2451.511 | V45: =V44+1 -> 11 | W45: =AF44 -> 68210.882 | X45: =IF(OR(W45<=0,V45>Financiamento_EV!$C$7),0,W45*Financiamento_EV!$C$9) -> 0 | Y45: =MAX(0,W45+X45) -> 68210.882 | Z45: =IF(Y45<=0,0,Y45*Financiamento_EV!$C$6) -> 1159.585 | AA45: =IF(Y45<=0,0,IF(Financiamento_EV!$C$6=0,Y45/(Financiamento_EV!$C$7-V45+1),Y45*Financiamento_EV!$C$6/(1-(1+Financiamento_EV!$C$6)^(-(Financiamento_EV!$C$7-V45+1))))) -> 2451.511 | AB45: =MAX(0,MIN(Y45,AA45-Z45)) -> 1291.926 | AC45: =IF(Y45<=0,0,MIN(IF(ISNUMBER(INDEX(Financiamento_EV!$I$17:$I$136,V45)),MAX(0,INDEX(Financiamento_EV!$I$17:$I$136,V45)),IF(V45>=Financiamento_EV!$C$11,Financiamento_EV!$C$10,0)),MAX(0,Y45-AB45))) -> 0 | AD45: =IF(OR(Y45<=0,V45<Financiamento_EV!$C$11),0,MIN(MAX(0,Financiamento_EV!$F$5-AA45),MAX(0,Y45-AB45-AC45))) -> 2.2737368e-12 | AE45: =IF(Y45<=0,0,AA45+AC45+AD45) -> 2451.511 | AF45: =MAX(0,Y45-AB45-AC45-AD45) -> 66918.956 | AG45: =AC45+AD45 -> 2.2737368e-12 | AI45: =A45 -> 11 | AJ45: =H45 -> 66918.956 | AK45: =S45 -> 66918.956 | AL45: =AF45 -> 66918.956 | AM45: =A45 -> 11 | AN45: =I45 -> 2451.511 | AO45: =T45 -> 2451.511 | AP45: =AE45 -> 2451.511
A46: =A45+1 -> 12 | B46: =H45 -> 66918.956 | C46: =IF(OR(B46<=0,A46>Financiamento_EV!$C$7),0,B46*Financiamento_EV!$C$9) -> 0 | D46: =MAX(0,B46+C46) -> 66918.956 | E46: =IF(D46<=0,0,D46*Financiamento_EV!$C$6) -> 1137.6222 | F46: =IF(D46<=0,0,IF(Financiamento_EV!$C$6=0,D46/(Financiamento_EV!$C$7-A46+1),D46*Financiamento_EV!$C$6/(1-(1+Financiamento_EV!$C$6)^(-(Financiamento_EV!$C$7-A46+1))))) -> 2451.511 | G46: =MAX(0,MIN(D46,F46-E46)) -> 1313.8887 | H46: =MAX(0,D46-G46) -> 65605.067 | I46: =IF(D46<=0,0,F46) -> 2451.511 | K46: =K45+1 -> 12 | L46: =S45 -> 66918.956 | M46: =IF(OR(L46<=0,K46>Financiamento_EV!$C$7),0,L46*Financiamento_EV!$C$9) -> 0 | N46: =MAX(0,L46+M46) -> 66918.956 | O46: =IF(N46<=0,0,N46*Financiamento_EV!$C$6) -> 1137.6222 | P46: =IF(N46<=0,0,IF(Financiamento_EV!$C$6=0,N46/(Financiamento_EV!$C$7-K46+1),N46*Financiamento_EV!$C$6/(1-(1+Financiamento_EV!$C$6)^(-(Financiamento_EV!$C$7-K46+1))))) -> 2451.511 | Q46: =MAX(0,MIN(N46,P46-O46)) -> 1313.8887 | R46: =IF(N46<=0,0,MIN(IF(ISNUMBER(INDEX(Financiamento_EV!$I$17:$I$136,K46)),MAX(0,INDEX(Financiamento_EV!$I$17:$I$136,K46)),IF(K46>=Financiamento_EV!$C$11,Financiamento_EV!$C$10,0)),MAX(0,N46-Q46))) -> 0 | S46: =MAX(0,N46-Q46-R46) -> 65605.067 | T46: =IF(N46<=0,0,P46+R46) -> 2451.511 | V46: =V45+1 -> 12 | W46: =AF45 -> 66918.956 | X46: =IF(OR(W46<=0,V46>Financiamento_EV!$C$7),0,W46*Financiamento_EV!$C$9) -> 0 | Y46: =MAX(0,W46+X46) -> 66918.956 | Z46: =IF(Y46<=0,0,Y46*Financiamento_EV!$C$6) -> 1137.6222 | AA46: =IF(Y46<=0,0,IF(Financiamento_EV!$C$6=0,Y46/(Financiamento_EV!$C$7-V46+1),Y46*Financiamento_EV!$C$6/(1-(1+Financiamento_EV!$C$6)^(-(Financiamento_EV!$C$7-V46+1))))) -> 2451.511 | AB46: =MAX(0,MIN(Y46,AA46-Z46)) -> 1313.8887 | AC46: =IF(Y46<=0,0,MIN(IF(ISNUMBER(INDEX(Financiamento_EV!$I$17:$I$136,V46)),MAX(0,INDEX(Financiamento_EV!$I$17:$I$136,V46)),IF(V46>=Financiamento_EV!$C$11,Financiamento_EV!$C$10,0)),MAX(0,Y46-AB46))) -> 0 | AD46: =IF(OR(Y46<=0,V46<Financiamento_EV!$C$11),0,MIN(MAX(0,Financiamento_EV!$F$5-AA46),MAX(0,Y46-AB46-AC46))) -> 1.8189894e-12 | AE46: =IF(Y46<=0,0,AA46+AC46+AD46) -> 2451.511 | AF46: =MAX(0,Y46-AB46-AC46-AD46) -> 65605.067 | AG46: =AC46+AD46 -> 1.8189894e-12 | AI46: =A46 -> 12 | AJ46: =H46 -> 65605.067 | AK46: =S46 -> 65605.067 | AL46: =AF46 -> 65605.067 | AM46: =A46 -> 12 | AN46: =I46 -> 2451.511 | AO46: =T46 -> 2451.511 | AP46: =AE46 -> 2451.511
A47: =A46+1 -> 13 | B47: =H46 -> 65605.067 | C47: =IF(OR(B47<=0,A47>Financiamento_EV!$C$7),0,B47*Financiamento_EV!$C$9) -> 0 | D47: =MAX(0,B47+C47) -> 65605.067 | E47: =IF(D47<=0,0,D47*Financiamento_EV!$C$6) -> 1115.2861 | F47: =IF(D47<=0,0,IF(Financiamento_EV!$C$6=0,D47/(Financiamento_EV!$C$7-A47+1),D47*Financiamento_EV!$C$6/(1-(1+Financiamento_EV!$C$6)^(-(Financiamento_EV!$C$7-A47+1))))) -> 2451.511 | G47: =MAX(0,MIN(D47,F47-E47)) -> 1336.2248 | H47: =MAX(0,D47-G47) -> 64268.842 | I47: =IF(D47<=0,0,F47) -> 2451.511 | K47: =K46+1 -> 13 | L47: =S46 -> 65605.067 | M47: =IF(OR(L47<=0,K47>Financiamento_EV!$C$7),0,L47*Financiamento_EV!$C$9) -> 0 | N47: =MAX(0,L47+M47) -> 65605.067 | O47: =IF(N47<=0,0,N47*Financiamento_EV!$C$6) -> 1115.2861 | P47: =IF(N47<=0,0,IF(Financiamento_EV!$C$6=0,N47/(Financiamento_EV!$C$7-K47+1),N47*Financiamento_EV!$C$6/(1-(1+Financiamento_EV!$C$6)^(-(Financiamento_EV!$C$7-K47+1))))) -> 2451.511 | Q47: =MAX(0,MIN(N47,P47-O47)) -> 1336.2248 | R47: =IF(N47<=0,0,MIN(IF(ISNUMBER(INDEX(Financiamento_EV!$I$17:$I$136,K47)),MAX(0,INDEX(Financiamento_EV!$I$17:$I$136,K47)),IF(K47>=Financiamento_EV!$C$11,Financiamento_EV!$C$10,0)),MAX(0,N47-Q47))) -> 0 | S47: =MAX(0,N47-Q47-R47) -> 64268.842 | T47: =IF(N47<=0,0,P47+R47) -> 2451.511 | V47: =V46+1 -> 13 | W47: =AF46 -> 65605.067 | X47: =IF(OR(W47<=0,V47>Financiamento_EV!$C$7),0,W47*Financiamento_EV!$C$9) -> 0 | Y47: =MAX(0,W47+X47) -> 65605.067 | Z47: =IF(Y47<=0,0,Y47*Financiamento_EV!$C$6) -> 1115.2861 | AA47: =IF(Y47<=0,0,IF(Financiamento_EV!$C$6=0,Y47/(Financiamento_EV!$C$7-V47+1),Y47*Financiamento_EV!$C$6/(1-(1+Financiamento_EV!$C$6)^(-(Financiamento_EV!$C$7-V47+1))))) -> 2451.511 | AB47: =MAX(0,MIN(Y47,AA47-Z47)) -> 1336.2248 | AC47: =IF(Y47<=0,0,MIN(IF(ISNUMBER(INDEX(Financiamento_EV!$I$17:$I$136,V47)),MAX(0,INDEX(Financiamento_EV!$I$17:$I$136,V47)),IF(V47>=Financiamento_EV!$C$11,Financiamento_EV!$C$10,0)),MAX(0,Y47-AB47))) -> 0 | AD47: =IF(OR(Y47<=0,V47<Financiamento_EV!$C$11),0,MIN(MAX(0,Financiamento_EV!$F$5-AA47),MAX(0,Y47-AB47-AC47))) -> 2.7284841e-12 | AE47: =IF(Y47<=0,0,AA47+AC47+AD47) -> 2451.511 | AF47: =MAX(0,Y47-AB47-AC47-AD47) -> 64268.842 | AG47: =AC47+AD47 -> 2.7284841e-12 | AI47: =A47 -> 13 | AJ47: =H47 -> 64268.842 | AK47: =S47 -> 64268.842 | AL47: =AF47 -> 64268.842 | AM47: =A47 -> 13 | AN47: =I47 -> 2451.511 | AO47: =T47 -> 2451.511 | AP47: =AE47 -> 2451.511
... A94: =A93+1 -> 60 | B94: =H93 -> 0 | C94: =IF(OR(B94<=0,A94>Financiamento_EV!$C$7),0,B94*Financiamento_EV!$C$9) -> 0 | D94: =MAX(0,B94+C94) -> 0 | E94: =IF(D94<=0,0,D94*Financiamento_EV!$C$6) -> 0 | F94: =IF(D94<=0,0,IF(Financiamento_EV!$C$6=0,D94/(Financiamento_EV!$C$7-A94+1),D94*Financiamento_EV!$C$6/(1-(1+Financiamento_EV!$C$6)^(-(Financiamento_EV!$C$7-A94+1))))) -> 0 | G94: =MAX(0,MIN(D94,F94-E94)) -> 0 | H94: =MAX(0,D94-G94) -> 0 | I94: =IF(D94<=0,0,F94) -> 0 | K94: =K93+1 -> 60 | L94: =S93 -> 0 | M94: =IF(OR(L94<=0,K94>Financiamento_EV!$C$7),0,L94*Financiamento_EV!$C$9) -> 0 | N94: =MAX(0,L94+M94) -> 0 | O94: =IF(N94<=0,0,N94*Financiamento_EV!$C$6) -> 0 | P94: =IF(N94<=0,0,IF(Financiamento_EV!$C$6=0,N94/(Financiamento_EV!$C$7-K94+1),N94*Financiamento_EV!$C$6/(1-(1+Financiamento_EV!$C$6)^(-(Financiamento_EV!$C$7-K94+1))))) -> 0 | Q94: =MAX(0,MIN(N94,P94-O94)) -> 0 | R94: =IF(N94<=0,0,MIN(IF(ISNUMBER(INDEX(Financiamento_EV!$I$17:$I$136,K94)),MAX(0,INDEX(Financiamento_EV!$I$17:$I$136,K94)),IF(K94>=Financiamento_EV!$C$11,Financiamento_EV!$C$10,0)),MAX(0,N94-Q94))) -> 0 | S94: =MAX(0,N94-Q94-R94) -> 0 | T94: =IF(N94<=0,0,P94+R94) -> 0 | V94: =V93+1 -> 60 | W94: =AF93 -> 0 | X94: =IF(OR(W94<=0,V94>Financiamento_EV!$C$7),0,W94*Financiamento_EV!$C$9) -> 0 | Y94: =MAX(0,W94+X94) -> 0 | Z94: =IF(Y94<=0,0,Y94*Financiamento_EV!$C$6) -> 0 | AA94: =IF(Y94<=0,0,IF(Financiamento_EV!$C$6=0,Y94/(Financiamento_EV!$C$7-V94+1),Y94*Financiamento_EV!$C$6/(1-(1+Financiamento_EV!$C$6)^(-(Financiamento_EV!$C$7-V94+1))))) -> 0 | AB94: =MAX(0,MIN(Y94,AA94-Z94)) -> 0 | AC94: =IF(Y94<=0,0,MIN(IF(ISNUMBER(INDEX(Financiamento_EV!$I$17:$I$136,V94)),MAX(0,INDEX(Financiamento_EV!$I$17:$I$136,V94)),IF(V94>=Financiamento_EV!$C$11,Financiamento_EV!$C$10,0)),MAX(0,Y94-AB94))) -> 0 | AD94: =IF(OR(Y94<=0,V94<Financiamento_EV!$C$11),0,MIN(MAX(0,Financiamento_EV!$F$5-AA94),MAX(0,Y94-AB94-AC94))) -> 0 | AE94: =IF(Y94<=0,0,AA94+AC94+AD94) -> 0 | AF94: =MAX(0,Y94-AB94-AC94-AD94) -> 0 | AG94: =AC94+AD94 -> 0 | AI94: =A94 -> 60 | AJ94: =H94 -> 0 | AK94: =S94 -> 0 | AL94: =AF94 -> 0 | AM94: =A94 -> 60 | AN94: =I94 -> 0 | AO94: =T94 -> 0 | AP94: =AE94 -> 0
